Workbook

Sheet 📋 Dados Brutos
A1: 📋 BASE DE DADOS — COLABORADORES
A2: Data | B2: ID Colaborador | C2: Nome | D2: Departamento | E2: Cargo | F2: Salário (R$) | G2: Status | H2: Motivo Saída | I2: Dias Afastamento | J2: Pontuação eNPS | K2: Horas Trabalhadas | L2: Horas Ausentes | M2: Data Admissão | N2: Data Desligamento | O2: Treinamentos (R$)
A3: 45689 | B3: COL-001 | C3: Colaborador 1 | D3: Operações | E3: Coordenador | F3: 4380 | G3: Ativo | I3: 0 | J3: 9 | K3: 176 | L3: 0 | M3: 44228 | O3: 550
A4: 45717 | B4: COL-002 | C4: Colaborador 2 | D4: RH | E4: Gerente | F4: 4760 | G4: Ativo | I4: 0 | J4: 8 | K4: 176 | L4: 0 | M4: 44256 | O4: 600
A5: 45748 | B5: COL-003 | C5: Colaborador 3 | D5: Financeiro | E5: Especialista | F5: 5140 | G5: Ativo | I5: 0 | J5: 8 | K5: 176 | L5: 0 | M5: 44287 | O5: 650
A6: 45778 | B6: COL-004 | C6: Colaborador 4 | D6: Tecnologia | E6: Assistente | F6: 5520 | G6: Ativo | I6: 0 | J6: 7 | K6: 176 | L6: 0 | M6: 44317 | O6: 700
A7: 45809 | B7: COL-005 | C7: Colaborador 5 | D7: Marketing | E7: Supervisor | F7: 5900 | G7: Ativo | I7: 1 | J7: 7 | K7: 176 | L7: 8 | M7: 44348 | O7: 750
A8: 45839 | B8: COL-006 | C8: Colaborador 6 | D8: Logística | E8: Analista | F8: 6280 | G8: Ativo | I8: 0 | J8: 6 | K8: 176 | L8: 0 | M8: 44378 | O8: 800
A9: 45870 | B9: COL-007 | C9: Colaborador 7 | D9: Comercial | E9: Coordenador | F9: 6660 | G9: Ativo | I9: 0 | J9: 5 | K9: 176 | L9: 0 | M9: 44409 | O9: 850
A10: 45901 | B10: COL-008 | C10: Colaborador 8 | D10: Operações | E10: Gerente | F10: 7040 | G10: Ativo | I10: 0 | J10: 4 | K10: 176 | L10: 0 | M10: 44440 | O10: 900
A11: 45658 | B11: COL-009 | C11: Colaborador 9 | D11: RH | E11: Especialista | F11: 7420 | G11: Ativo | I11: 0 | J11: 3 | K11: 176 | L11: 0 | M11: 44197 | O11: 950
A12: 45689 | B12: COL-010 | C12: Colaborador 10 | D12: Financeiro | E12: Assistente | F12: 7800 | G12: Ativo | I12: 7 | J12: 2 | K12: 176 | L12: 56 | M12: 44593 | O12: 1000
A13: 45717 | B13: COL-011 | C13: Colaborador 11 | D13: Tecnologia | E13: Supervisor | F13: 8180 | G13: Ativo | I13: 0 | J13: 1 | K13: 176 | L13: 0 | M13: 44621 | O13: 1050
A14: 45748 | B14: COL-012 | C14: Colaborador 12 | D14: Marketing | E14: Analista | F14: 8560 | G14: Ativo | I14: 0 | J14: 0 | K14: 176 | L14: 0 | M14: 44652 | O14: 1100
... A26: 45839 | B26: COL-024 | C26: Colaborador 24 | D26: Financeiro | E26: Analista | F26: 13120 | G26: Ativo | I26: 0 | J26: 2 | K26: 176 | L26: 0 | M26: 45108 | O26: 1700
A27: 45870 | B27: COL-025 | C27: Colaborador 25 | D27: Tecnologia | E27: Coordenador | F27: 13500 | G27: Desligado | H27: Involuntário | I27: 8 | J27: 1 | K27: 176 | L27: 64 | M27: 45139 | N27: 45884 | O27: 0
A28: 45901 | B28: COL-026 | C28: Colaborador 26 | D28: Marketing | E28: Gerente | F28: 13880 | G28: Desligado | H28: Aposentadoria | I28: 0 | J28: 0 | K28: 176 | L28: 0 | M28: 45170 | N28: 45915 | O28: 0
A29: 45658 | B29: COL-027 | C29: Colaborador 27 | D29: Logística | E29: Especialista | F29: 14260 | G29: Desligado | H29: Voluntário | I29: 0 | J29: -1 | K29: 176 | L29: 0 | M29: 44927 | N29: 45672 | O29: 0
A30: 45689 | B30: COL-028 | C30: Colaborador 28 | D30: Comercial | E30: Assistente | F30: 14640 | G30: Desligado | H30: Involuntário | I30: 0 | J30: 10 | K30: 176 | L30: 0 | M30: 44958 | N30: 45703 | O30: 0
A31: 45717 | B31: COL-029 | C31: Colaborador 29 | D31: Operações | E31: Supervisor | F31: 15020 | G31: Desligado | H31: Aposentadoria | I31: 0 | J31: 9 | K31: 176 | L31: 0 | M31: 44986 | N31: 45731 | O31: 0
A32: 45748 | B32: COL-030 | C32: Colaborador 30 | D32: RH | E32: Analista | F32: 15400 | G32: Desligado | H32: Voluntário | I32: 7 | J32: 8 | K32: 176 | L32: 56 | M32: 45383 | N32: 45762 | O32: 0

Sheet 📊 Indicadores Críticos
A1: 📊 INDICADORES CRÍTICOS DE RH
A3: 🔴 TURNOVER MENSAL
A4: Mês | B4: Ativos (início) | C4: Admissões | D4: Demissões | E4: Média Período | F4: Turnover (%) | G4: Benchmark (%) | H4: Δ (p.p.) | I4: Status
A5: 46047 | B5: 120 | C5: 3 | D5: 2 | E5: =(C5+D5)/2 -> 2.5 | F5: =((C5+D5)/2)/B5*100 -> 2.0833333 | G5: 15 | H5: =F5-G5 -> -12.916667 | I5: =IF(F5<=G5,"✅ OK","⚠️ Acima") -> ✅ OK
A6: 46078 | B6: 122 | C6: 2 | D6: 4 | E6: =(C6+D6)/2 -> 3 | F6: =((C6+D6)/2)/B6*100 -> 2.4590164 | G6: 15 | H6: =F6-G6 -> -12.540984 | I6: =IF(F6<=G6,"✅ OK","⚠️ Acima") -> ✅ OK
A7: 46106 | B7: 120 | C7: 5 | D7: 1 | E7: =(C7+D7)/2 -> 3 | F7: =((C7+D7)/2)/B7*100 -> 2.5 | G7: 15 | H7: =F7-G7 -> -12.5 | I7: =IF(F7<=G7,"✅ OK","⚠️ Acima") -> ✅ OK
A8: 46137 | B8: 124 | C8: 1 | D8: 3 | E8: =(C8+D8)/2 -> 2 | F8: =((C8+D8)/2)/B8*100 -> 1.6129032 | G8: 15 | H8: =F8-G8 -> -13.387097 | I8: =IF(F8<=G8,"✅ OK","⚠️ Acima") -> ✅ OK
A9: 46167 | B9: 122 | C9: 4 | D9: 2 | E9: =(C9+D9)/2 -> 3 | F9: =((C9+D9)/2)/B9*100 -> 2.4590164 | G9: 15 | H9: =F9-G9 -> -12.540984 | I9: =IF(F9<=G9,"✅ OK","⚠️ Acima") -> ✅ OK
A10: 46198 | B10: 124 | C10: 3 | D10: 5 | E10: =(C10+D10)/2 -> 4 | F10: =((C10+D10)/2)/B10*100 -> 3.2258065 | G10: 15 | H10: =F10-G10 -> -11.774194 | I10: =IF(F10<=G10,"✅ OK","⚠️ Acima") -> ✅ OK
A11: 46228 | B11: 122 | C11: 2 | D11: 2 | E11: =(C11+D11)/2 -> 2 | F11: =((C11+D11)/2)/B11*100 -> 1.6393443 | G11: 15 | H11: =F11-G11 -> -13.360656 | I11: =IF(F11<=G11,"✅ OK","⚠️ Acima") -> ✅ OK
A12: 46259 | B12: 122 | C12: 3 | D12: 3 | E12: =(C12+D12)/2 -> 3 | F12: =((C12+D12)/2)/B12*100 -> 2.4590164 | G12: 15 | H12: =F12-G12 -> -12.540984 | I12: =IF(F12<=G12,"✅ OK","⚠️ Acima") -> ✅ OK
A13: 46290 | B13: 122 | C13: 4 | D13: 1 | E13: =(C13+D13)/2 -> 2.5 | F13: =((C13+D13)/2)/B13*100 -> 2.0491803 | G13: 15 | H13: =F13-G13 -> -12.95082 | I13: =IF(F13<=G13,"✅ OK","⚠️ Acima") -> ✅ OK
A14: 46320 | B14: 125 | C14: 2 | D14: 4 | E14: =(C14+D14)/2 -> 3 | F14: =((C14+D14)/2)/B14*100 -> 2.4 | G14: 15 | H14: =F14-G14 -> -12.6 | I14: =IF(F14<=G14,"✅ OK","⚠️ Acima") -> ✅ OK
A15: 46351 | B15: 123 | C15: 3 | D15: 2 | E15: =(C15+D15)/2 -> 2.5 | F15: =((C15+D15)/2)/B15*100 -> 2.0325203 | G15: 15 | H15: =F15-G15 -> -12.96748 | I15: =IF(F15<=G15,"✅ OK","⚠️ Acima") -> ✅ OK
A16: 46381 | B16: 124 | C16: 1 | D16: 3 | E16: =(C16+D16)/2 -> 2 | F16: =((C16+D16)/2)/B16*100 -> 1.6129032 | G16: 15 | H16: =F16-G16 -> -13.387097 | I16: =IF(F16<=G16,"✅ OK","⚠️ Acima") -> ✅ OK
A19: 🟡 ABSENTEÍSMO INDUSTRIAL
A20: Mês | B20: Horas Trabalhadas | C20: Horas Ausentes | D20: Taxa (%) | E20: Benchmark (%) | F20: Δ vs Benchmark | G20: Custo Est. (R$) | H20: Status
A21: 46047 | B21: 2640 | C21: 52 | D21: =(C21/B21)*100 -> 1.969697 | E21: 2 | F21: =D21-E21 -> -0.03030303 | G21: =C21*35 -> 1820 | H21: =IF(D21<=E21,"✅ Normal","🔴 Crítico") -> ✅ Normal
A22: 46078 | B22: 2640 | C22: 48 | D22: =(C22/B22)*100 -> 1.8181818 | E22: 2 | F22: =D22-E22 -> -0.18181818 | G22: =C22*35 -> 1680 | H22: =IF(D22<=E22,"✅ Normal","🔴 Crítico") -> ✅ Normal
A23: 46106 | B23: 2640 | C23: 60 | D23: =(C23/B23)*100 -> 2.2727273 | E23: 2 | F23: =D23-E23 -> 0.27272727 | G23: =C23*35 -> 2100 | H23: =IF(D23<=E23,"✅ Normal","🔴 Crítico") -> 🔴 Crítico
A24: 46137 | B24: 2640 | C24: 44 | D24: =(C24/B24)*100 -> 1.6666667 | E24: 2 | F24: =D24-E24 -> -0.33333333 | G24: =C24*35 -> 1540 | H24: =IF(D24<=E24,"✅ Normal","🔴 Crítico") -> ✅ Normal
A25: 46167 | B25: 2640 | C25: 72 | D25: =(C25/B25)*100 -> 2.7272727 | E25: 2 | F25: =D25-E25 -> 0.72727273 | G25: =C25*35 -> 2520 | H25: =IF(D25<=E25,"✅ Normal","🔴 Crítico") -> 🔴 Crítico
A26: 46198 | B26: 2640 | C26: 55 | D26: =(C26/B26)*100 -> 2.0833333 | E26: 2 | F26: =D26-E26 -> 0.083333333 | G26: =C26*35 -> 1925 | H26: =IF(D26<=E26,"✅ Normal","🔴 Crítico") -> 🔴 Crítico
A27: 46228 | B27: 2640 | C27: 48 | D27: =(C27/B27)*100 -> 1.8181818 | E27: 2 | F27: =D27-E27 -> -0.18181818 | G27: =C27*35 -> 1680 | H27: =IF(D27<=E27,"✅ Normal","🔴 Crítico") -> ✅ Normal
A28: 46259 | B28: 2640 | C28: 65 | D28: =(C28/B28)*100 -> 2.4621212 | E28: 2 | F28: =D28-E28 -> 0.46212121 | G28: =C28*35 -> 2275 | H28: =IF(D28<=E28,"✅ Normal","🔴 Crítico") -> 🔴 Crítico
A29: 46290 | B29: 2640 | C29: 58 | D29: =(C29/B29)*100 -> 2.1969697 | E29: 2 | F29: =D29-E29 -> 0.1969697 | G29: =C29*35 -> 2030 | H29: =IF(D29<=E29,"✅ Normal","🔴 Crítico") -> 🔴 Crítico
A30: 46320 | B30: 2640 | C30: 42 | D30: =(C30/B30)*100 -> 1.5909091 | E30: 2 | F30: =D30-E30 -> -0.40909091 | G30: =C30*35 -> 1470 | H30: =IF(D30<=E30,"✅ Normal","🔴 Crítico") -> ✅ Normal
A31: 46351 | B31: 2640 | C31: 70 | D31: =(C31/B31)*100 -> 2.6515152 | E31: 2 | F31: =D31-E31 -> 0.65151515 | G31: =C31*35 -> 2450 | H31: =IF(D31<=E31,"✅ Normal","🔴 Crítico") -> 🔴 Crítico
A32: 46381 | B32: 2640 | C32: 50 | D32: =(C32/B32)*100 -> 1.8939394 | E32: 2 | F32: =D32-E32 -> -0.10606061 | G32: =C32*35 -> 1750 | H32: =IF(D32<=E32,"✅ Normal","🔴 Crítico") -> ✅ Normal
A35: 🟢 eNPS — ENGAJAMENTO
A36: Mês | B36: Total Resp. | C36: Promotores | D36: Neutros | E36: Detratores | F36: % Promotores | G36: % Detratores | H36: eNPS | I36: Classificação
A37: 46047 | B37: 85 | C37: 42 | D37: 30 | E37: 13 | F37: =(C37/B37)*100 -> 49.411765 | G37: =(E37/B37)*100 -> 15.294118 | H37: =F37-G37 -> 34.117647 | I37: =IF(H37>=50,"🟢 Excelente",IF(H37>=20,"🟡 Bom",IF(H37>=0,"🟠 Regular","🔴 Crítico"))) -> 🟡 Bom
A38: 46078 | B38: 88 | C38: 44 | D38: 31 | E38: 13 | F38: =(C38/B38)*100 -> 50 | G38: =(E38/B38)*100 -> 14.772727 | H38: =F38-G38 -> 35.227273 | I38: =IF(H38>=50,"🟢 Excelente",IF(H38>=20,"🟡 Bom",IF(H38>=0,"🟠 Regular","🔴 Crítico"))) -> 🟡 Bom
A39: 46106 | B39: 90 | C39: 40 | D39: 35 | E39: 15 | F39: =(C39/B39)*100 -> 44.444444 | G39: =(E39/B39)*100 -> 16.666667 | H39: =F39-G39 -> 27.777778 | I39: =IF(H39>=50,"🟢 Excelente",IF(H39>=20,"🟡 Bom",IF(H39>=0,"🟠 Regular","🔴 Crítico"))) -> 🟡 Bom
A40: 46137 | B40: 87 | C40: 50 | D40: 25 | E40: 12 | F40: =(C40/B40)*100 -> 57.471264 | G40: =(E40/B40)*100 -> 13.793103 | H40: =F40-G40 -> 43.678161 | I40: =IF(H40>=50,"🟢 Excelente",IF(H40>=20,"🟡 Bom",IF(H40>=0,"🟠 Regular","🔴 Crítico"))) -> 🟡 Bom
A41: 46167 | B41: 92 | C41: 55 | D41: 25 | E41: 12 | F41: =(C41/B41)*100 -> 59.782609 | G41: =(E41/B41)*100 -> 13.043478 | H41: =F41-G41 -> 46.73913 | I41: =IF(H41>=50,"🟢 Excelente",IF(H41>=20,"🟡 Bom",IF(H41>=0,"🟠 Regular","🔴 Crítico"))) -> 🟡 Bom
A42: 46198 | B42: 95 | C42: 52 | D42: 30 | E42: 13 | F42: =(C42/B42)*100 -> 54.736842 | G42: =(E42/B42)*100 -> 13.684211 | H42: =F42-G42 -> 41.052632 | I42: =IF(H42>=50,"🟢 Excelente",IF(H42>=20,"🟡 Bom",IF(H42>=0,"🟠 Regular","🔴 Crítico"))) -> 🟡 Bom
A43: 46228 | B43: 88 | C43: 48 | D43: 28 | E43: 12 | F43: =(C43/B43)*100 -> 54.545455 | G43: =(E43/B43)*100 -> 13.636364 | H43: =F43-G43 -> 40.909091 | I43: =IF(H43>=50,"🟢 Excelente",IF(H43>=20,"🟡 Bom",IF(H43>=0,"🟠 Regular","🔴 Crítico"))) -> 🟡 Bom
A44: 46259 | B44: 91 | C44: 50 | D44: 28 | E44: 13 | F44: =(C44/B44)*100 -> 54.945055 | G44: =(E44/B44)*100 -> 14.285714 | H44: =F44-G44 -> 40.659341 | I44: =IF(H44>=50,"🟢 Excelente",IF(H44>=20,"🟡 Bom",IF(H44>=0,"🟠 Regular","🔴 Crítico"))) -> 🟡 Bom
A45: 46290 | B45: 89 | C45: 46 | D45: 30 | E45: 13 | F45: =(C45/B45)*100 -> 51.685393 | G45: =(E45/B45)*100 -> 14.606742 | H45: =F45-G45 -> 37.078652 | I45: =IF(H45>=50,"🟢 Excelente",IF(H45>=20,"🟡 Bom",IF(H45>=0,"🟠 Regular","🔴 Crítico"))) -> 🟡 Bom
...

Sheet 💰 Financeiro & EBITDA
A1: 💰 IMPACTO FINANCEIRO DO CAPITAL HUMANO — EBITDA
A3: 💸 CUSTO DE ATTRITION | J3: 🎯 PAINEL EBITDA
A4: Mês | B4: Nº Demissões | C4: Salário Médio (R$) | D4: Custo Unit. (1,5×sal.anual) | E4: Custo Total Mensal (R$) | F4: Custo Acumulado (R$) | G4: Impacto EBITDA (%) | H4: EBITDA Mensal (R$) | J4: EBITDA Mensal Médio | K4: =AVERAGE(H5:H16) -> 850000
A5: 46047 | B5: 2 | C5: 8500 | D5: =C5*12*1.5 -> 153000 | E5: =B5*D5 -> 306000 | F5: =E5 -> 306000 | G5: =(E5/H5)*100 -> 36 | H5: 850000 | J5: Custo Attrition Total Ano | K5: =F17 -> 4896000
A6: 46078 | B6: 4 | C6: 8500 | D6: =C6*12*1.5 -> 153000 | E6: =B6*D6 -> 612000 | F6: =F5+E6 -> 918000 | G6: =(E6/H6)*100 -> 72 | H6: 850000 | J6: % EBITDA consumido (Attrition) | K6: =F17/SUM(H5:H16)*100 -> 48
A7: 46106 | B7: 1 | C7: 8500 | D7: =C7*12*1.5 -> 153000 | E7: =B7*D7 -> 153000 | F7: =F6+E7 -> 1071000 | G7: =(E7/H7)*100 -> 18 | H7: 850000 | J7: Receita média por FTE | K7: =AVERAGE(D21:D32) -> 10586.821
A8: 46137 | B8: 3 | C8: 8500 | D8: =C8*12*1.5 -> 153000 | E8: =B8*D8 -> 459000 | F8: =F7+E8 -> 1530000 | G8: =(E8/H8)*100 -> 54 | H8: 850000 | J8: ROI médio Treinamento (%) | K8: =AVERAGE(D37:D48) -> 86.968288
A9: 46167 | B9: 2 | C9: 8500 | D9: =C9*12*1.5 -> 153000 | E9: =B9*D9 -> 306000 | F9: =F8+E9 -> 1836000 | G9: =(E9/H9)*100 -> 36 | H9: 850000 | J9: Invest. total Treinamento | K9: =SUM(B37:B48) -> 187000
A10: 46198 | B10: 5 | C10: 8500 | D10: =C10*12*1.5 -> 153000 | E10: =B10*D10 -> 765000 | F10: =F9+E10 -> 2601000 | G10: =(E10/H10)*100 -> 90 | H10: 850000 | J10: Ganho total Produtividade | K10: =SUM(C37:C48) -> 350000
A11: 46228 | B11: 2 | C11: 8500 | D11: =C11*12*1.5 -> 153000 | E11: =B11*D11 -> 306000 | F11: =F10+E11 -> 2907000 | G11: =(E11/H11)*100 -> 36 | H11: 850000
A12: 46259 | B12: 3 | C12: 8500 | D12: =C12*12*1.5 -> 153000 | E12: =B12*D12 -> 459000 | F12: =F11+E12 -> 3366000 | G12: =(E12/H12)*100 -> 54 | H12: 850000
A13: 46290 | B13: 1 | C13: 8500 | D13: =C13*12*1.5 -> 153000 | E13: =B13*D13 -> 153000 | F13: =F12+E13 -> 3519000 | G13: =(E13/H13)*100 -> 18 | H13: 850000
A14: 46320 | B14: 4 | C14: 8500 | D14: =C14*12*1.5 -> 153000 | E14: =B14*D14 -> 612000 | F14: =F13+E14 -> 4131000 | G14: =(E14/H14)*100 -> 72 | H14: 850000
A15: 46351 | B15: 2 | C15: 8500 | D15: =C15*12*1.5 -> 153000 | E15: =B15*D15 -> 306000 | F15: =F14+E15 -> 4437000 | G15: =(E15/H15)*100 -> 36 | H15: 850000
A16: 46381 | B16: 3 | C16: 8500 | D16: =C16*12*1.5 -> 153000 | E16: =B16*D16 -> 459000 | F16: =F15+E16 -> 4896000 | G16: =(E16/H16)*100 -> 54 | H16: 850000
A17: TOTAL ANO | B17: =SUM(B5:B16) -> 32 | E17: =SUM(E5:E16) -> 4896000 | F17: =F16 -> 4896000 | G17: =SUM(G5:G16) -> 576
A19: 📈 FTE PRODUCTIVITY — RECEITA POR COLABORADOR
A20: Mês | B20: Receita Total (R$) | C20: Total FTEs | D20: Receita por FTE (R$) | E20: Meta por FTE (R$) | F20: Δ vs Meta (R$) | G20: Δ vs Meta (%) | H20: Status
A21: 46047 | B21: 1200000 | C21: 122 | D21: =B21/C21 -> 9836.0656 | E21: 10000 | F21: =D21-E21 -> -163.93443 | G21: =((D21-E21)/E21)*100 -> -1.6393443 | H21: =IF(D21>=E21,"✅ Meta atingida","⚠️ Abaixo da meta") -> ⚠️ Abaixo da meta
A22: 46078 | B22: 1150000 | C22: 120 | D22: =B22/C22 -> 9583.3333 | E22: 10000 | F22: =D22-E22 -> -416.66667 | G22: =((D22-E22)/E22)*100 -> -4.1666667 | H22: =IF(D22>=E22,"✅ Meta atingida","⚠️ Abaixo da meta") -> ⚠️ Abaixo da meta
A23: 46106 | B23: 1300000 | C23: 124 | D23: =B23/C23 -> 10483.871 | E23: 10000 | F23: =D23-E23 -> 483.87097 | G23: =((D23-E23)/E23)*100 -> 4.8387097 | H23: =IF(D23>=E23,"✅ Meta atingida","⚠️ Abaixo da meta") -> ✅ Meta atingida
A24: 46137 | B24: 1180000 | C24: 122 | D24: =B24/C24 -> 9672.1311 | E24: 10000 | F24: =D24-E24 -> -327.86885 | G24: =((D24-E24)/E24)*100 -> -3.2786885 | H24: =IF(D24>=E24,"✅ Meta atingida","⚠️ Abaixo da meta") -> ⚠️ Abaixo da meta
A25: 46167 | B25: 1350000 | C25: 125 | D25: =B25/C25 -> 10800 | E25: 10000 | F25: =D25-E25 -> 800 | G25: =((D25-E25)/E25)*100 -> 8 | H25: =IF(D25>=E25,"✅ Meta atingida","⚠️ Abaixo da meta") -> ✅ Meta atingida
A26: 46198 | B26: 1280000 | C26: 123 | D26: =B26/C26 -> 10406.504 | E26: 10000 | F26: =D26-E26 -> 406.50407 | G26: =((D26-E26)/E26)*100 -> 4.0650407 | H26: =IF(D26>=E26,"✅ Meta atingida","⚠️ Abaixo da meta") -> ✅ Meta atingida
A27: 46228 | B27: 1310000 | C27: 122 | D27: =B27/C27 -> 10737.705 | E27: 10000 | F27: =D27-E27 -> 737.70492 | G27: =((D27-E27)/E27)*100 -> 7.3770492 | H27: =IF(D27>=E27,"✅ Meta atingida","⚠️ Abaixo da meta") -> ✅ Meta atingida
A28: 46259 | B28: 1290000 | C28: 122 | D28: =B28/C28 -> 10573.77 | E28: 10000 | F28: =D28-E28 -> 573.77049 | G28: =((D28-E28)/E28)*100 -> 5.7377049 | H28: =IF(D28>=E28,"✅ Meta atingida","⚠️ Abaixo da meta") -> ✅ Meta atingida
A29: 46290 | B29: 1400000 | C29: 122 | D29: =B29/C29 -> 11475.41 | E29: 10000 | F29: =D29-E29 -> 1475.4098 | G29: =((D29-E29)/E29)*100 -> 14.754098 | H29: =IF(D29>=E29,"✅ Meta atingida","⚠️ Abaixo da meta") -> ✅ Meta atingida
A30: 46320 | B30: 1320000 | C30: 125 | D30: =B30/C30 -> 10560 | E30: 10000 | F30: =D30-E30 -> 560 | G30: =((D30-E30)/E30)*100 -> 5.6 | H30: =IF(D30>=E30,"✅ Meta atingida","⚠️ Abaixo da meta") -> ✅ Meta atingida
A31: 46351 | B31: 1380000 | C31: 123 | D31: =B31/C31 -> 11219.512 | E31: 10000 | F31: =D31-E31 -> 1219.5122 | G31: =((D31-E31)/E31)*100 -> 12.195122 | H31: =IF(D31>=E31,"✅ Meta atingida","⚠️ Abaixo da meta") -> ✅ Meta atingida
A32: 46381 | B32: 1450000 | C32: 124 | D32: =B32/C32 -> 11693.548 | E32: 10000 | F32: =D32-E32 -> 1693.5484 | G32: =((D32-E32)/E32)*100 -> 16.935484 | H32: =IF(D32>=E32,"✅ Meta atingida","⚠️ Abaixo da meta") -> ✅ Meta atingida
A35: 🎓 ROI DE TREINAMENTO
A36: Mês | B36: Investimento (R$) | C36: Ganho Produtividade (R$) | D36: ROI (%) | E36: Payback (meses) | F36: Status ROI
A37: 46047 | B37: 15000 | C37: 28000 | D37: =((C37-B37)/B37)*100 -> 86.666667 | E37: =(B37/C37)*12 -> 6.4285714 | F37: =IF(D37>=50,"🟢 Excelente",IF(D37>=20,"🟡 Bom","🔴 Revisar")) -> 🟢 Excelente
A38: 46078 | B38: 12000 | C38: 22000 | D38: =((C38-B38)/B38)*100 -> 83.333333 | E38: =(B38/C38)*12 -> 6.5454545 | F38: =IF(D38>=50,"🟢 Excelente",IF(D38>=20,"🟡 Bom","🔴 Revisar")) -> 🟢 Excelente
A39: 46106 | B39: 18000 | C39: 35000 | D39: =((C39-B39)/B39)*100 -> 94.444444 | E39: =(B39/C39)*12 -> 6.1714286 | F39: =IF(D39>=50,"🟢 Excelente",IF(D39>=20,"🟡 Bom","🔴 Revisar")) -> 🟢 Excelente
A40: 46137 | B40: 10000 | C40: 19000 | D40: =((C40-B40)/B40)*100 -> 90 | E40: =(B40/C40)*12 -> 6.3157895 | F40: =IF(D40>=50,"🟢 Excelente",IF(D40>=20,"🟡 Bom","🔴 Revisar")) -> 🟢 Excelente
A41: 46167 | B41: 22000 | C41: 40000 | D41: =((C41-B41)/B41)*100 -> 81.818182 | E41: =(B41/C41)*12 -> 6.6 | F41: =IF(D41>=50,"🟢 Excelente",IF(D41>=20,"🟡 Bom","🔴 Revisar")) -> 🟢 Excelente
A42: 46198 | B42: 14000 | C42: 26000 | D42: =((C42-B42)/B42)*100 -> 85.714286 | E42: =(B42/C42)*12 -> 6.4615385 | F42: =IF(D42>=50,"🟢 Excelente",IF(D42>=20,"🟡 Bom","🔴 Revisar")) -> 🟢 Excelente
A43: 46228 | B43: 16000 | C43: 30000 | D43: =((C43-B43)/B43)*100 -> 87.5 | E43: =(B43/C43)*12 -> 6.4 | F43: =IF(D43>=50,"🟢 Excelente",IF(D43>=20,"🟡 Bom","🔴 Revisar")) -> 🟢 Excelente
A44: 46259 | B44: 13000 | C44: 24000 | D44: =((C44-B44)/B44)*100 -> 84.615385 | E44: =(B44/C44)*12 -> 6.5 | F44: =IF(D44>=50,"🟢 Excelente",IF(D44>=20,"🟡 Bom","🔴 Revisar")) -> 🟢 Excelente
...

Sheet 🎯 Dashboard Executivo
A1: 🎯 DASHBOARD EXECUTIVO — CAPITAL HUMANO & EBITDA
A2: Visão Consolidada | Atualização mensal | Fonte: Dados Brutos + Indicadores + Financeiro
C4: TURNOVER ANUAL (%) | E4: eNPS ATUAL (pts) | G4: ABSENTEÍSMO MÉDIO (%) | I4: CUSTO ATTRITION/ANO | K4: FTE PRODUCTIVITY MÉD. | M4: ROI TREINAMENTO MÉD. (%)
C5: ='📊 Indicadores Críticos'!F16 -> 1.6129032 | E5: ='📊 Indicadores Críticos'!H48 -> 46.808511 | G5: =AVERAGE('📊 Indicadores Críticos'!D21:D32) -> 2.0959596 | I5: ='💰 Financeiro & EBITDA'!F17 -> 4896000 | K5: =AVERAGE('💰 Financeiro & EBITDA'!D21:D32) -> 10586.821 | M5: =AVERAGE('💰 Financeiro & EBITDA'!D37:D48) -> 86.968288
A7: ──────────────────── GRÁFICOS ────────────────────
A8: GRÁFICO 1 — VELOCÍMETRO: TURNOVER vs. BENCHMARK | I8: GRÁFICO 2 — CUSTO FINANCEIRO DO TURNOVER ACUMULADO
A20: GRÁFICO 3 — CORRELAÇÃO: eNPS vs. PRODUTIVIDADE | I20: GRÁFICO 4 — MATRIZ DE SUCESSÃO: POSIÇÕES CRÍTICAS
A32: 📌 TABELA — MATRIZ DE SUCESSÃO (preencha manualmente)
A33: Área | B33: Posições Críticas | C33: Com Sucessor | D33: Em Desenvolvimento | E33: Sem Sucessor | F33: % Cobertura | G33: Status
A34: Comercial | B34: 5 | C34: 3 | D34: 1 | E34: 1 | F34: =((C34+D34)/B34)*100 -> 80 | G34: =IF(F34>=80,"✅ Adequado",IF(F34>=50,"🟡 Atenção","🔴 Crítico")) -> ✅ Adequado
A35: Operações | B35: 8 | C35: 4 | D35: 2 | E35: 2 | F35: =((C35+D35)/B35)*100 -> 75 | G35: =IF(F35>=80,"✅ Adequado",IF(F35>=50,"🟡 Atenção","🔴 Crítico")) -> 🟡 Atenção
A36: Tecnologia | B36: 6 | C36: 2 | D36: 3 | E36: 1 | F36: =((C36+D36)/B36)*100 -> 83.333333 | G36: =IF(F36>=80,"✅ Adequado",IF(F36>=50,"🟡 Atenção","🔴 Crítico")) -> ✅ Adequado
A37: RH | B37: 3 | C37: 2 | D37: 1 | E37: 0 | F37: =((C37+D37)/B37)*100 -> 100 | G37: =IF(F37>=80,"✅ Adequado",IF(F37>=50,"🟡 Atenção","🔴 Crítico")) -> ✅ Adequado
A38: Financeiro | B38: 4 | C38: 3 | D38: 0 | E38: 1 | F38: =((C38+D38)/B38)*100 -> 75 | G38: =IF(F38>=80,"✅ Adequado",IF(F38>=50,"🟡 Atenção","🔴 Crítico")) -> 🟡 Atenção
A39: Logística | B39: 7 | C39: 3 | D39: 2 | E39: 2 | F39: =((C39+D39)/B39)*100 -> 71.428571 | G39: =IF(F39>=80,"✅ Adequado",IF(F39>=50,"🟡 Atenção","🔴 Crítico")) -> 🟡 Atenção
A41: ⚠️ Uso restrito ao Board Executivo | Dados atualizados mensalmente | Fórmulas automáticas vinculadas às abas internas
